<?xml version="1.0" ?>
<!-- =================================================================================== -->
<!-- |    This document was autogenerated by xacro from robot_properties_fingers/xacro/trifinger.urdf.xacro | -->
<!-- |    EDITING THIS FILE BY HAND IS NOT RECOMMENDED                                 | -->
<!-- =================================================================================== -->
<robot name="finger_with_stage">
  <!--
    Frames are defined such that they all align with the base frame when all
    joints are at position zero.

    In zero-configuration the origins of all joints are in one line.

    In zero-configuration the origin of the base link is exactly above the
    finger tip which should make it easy to place the finger in the world.
    -->
  <!-- Define the global base_link and place all other objects relative to it. -->
  
  <material name="finger_0_material">
    <color rgba="0.6 0.0 0.0 1.0"/>
  </material>
  <material name="finger_120_material">
    <color rgba="0.0 0.6 0.0 1.0"/>
  </material>
  <material name="finger_240_material">
    <color rgba="0.0 0.0 0.6 1.0"/>
  </material>
  
  <link name="base_link" />
  
  <!-- Finger 1 -->
  
  <link name="tip_link_1_real">
   <visual>
      <origin rpy="0 0 0" xyz="0 0 0"/>
      <geometry>
        <sphere radius=".01"/>
      </geometry>
      <material name="finger_0_material"/>
    </visual>
    <inertial>
      <origin rpy="0 0 0" xyz="0 0 0"/>
      <mass value="0.01"/>
    </inertial>
    <collision>
      <origin rpy="0 0 0" xyz="0 0 0"/>
      <geometry>
        <sphere radius=".01"/>
      </geometry>
    </collision>
  </link>
  
  <link name="tip_link_1_fake_x" />
  
  <link name="tip_link_1_fake_y" />
  
  <joint name="tip_link_1_to_base_x" type="prismatic">
    <parent link="base_link"/>
    <child link="tip_link_1_fake_x"/>
    <axis xyz="1 0 0"/>
  </joint>
  <joint name="tip_link_1_to_base_y" type="prismatic">
    <parent link="tip_link_1_fake_x"/>
    <child link="tip_link_1_fake_y"/>
    <axis xyz="0 1 0"/>
  </joint>
    <joint name="tip_link_1_to_base_z" type="prismatic">
    <parent link="tip_link_1_fake_y"/>
    <child link="tip_link_1_real"/>
    <axis xyz="0 0 1"/>
  </joint>
  
   <transmission name="tip_link_1_to_base_trans_x" type="SimpleTransmission">
    <actuator name="tip_link_1_to_base_act_x"/>
    <joint name="tip_link_1_to_base_x"/>
    <mechanicalReduction>1</mechanicalReduction>
  </transmission>
  
     <transmission name="tip_link_1_to_base_trans_y" type="SimpleTransmission">
    <actuator name="tip_link_1_to_base_act_y"/>
    <joint name="tip_link_1_to_base_y"/>
    <mechanicalReduction>1</mechanicalReduction>
  </transmission>
  
     <transmission name="tip_link_1_to_base_trans_z" type="SimpleTransmission">
    <actuator name="tip_link_1_to_base_act_z"/>
    <joint name="tip_link_1_to_base_z"/>
    <mechanicalReduction>1</mechanicalReduction>
  </transmission>
  
  <drake:collision_filter_group name="finger_0_group">
  <drake:member link="tip_link_1_real"/>
  <drake:ignored_collision_filter_group name="finger_0_group"/>
  </drake:collision_filter_group>
 
  
   <!-- Table -->
   
  <link name="box">
    <inertial>
      <mass value="1"/>
      <!-- Inertia values were calculated to be consistent with the mass and
           geometry size, assuming a uniform density. -->
     <inertia ixx="100"  ixy="0"  ixz="0" iyy="100" iyz="0" izz="100" />
    </inertial>
    <visual>
      <geometry>
        <box size="5 5 0.1"/>
      </geometry>
    </visual>
   <collision name="box">
      <geometry>
        <box size="5 5 0.1"/>
      </geometry>
    </collision>
    <contact>
            <!-- TODO: not sure if these values make sense -->
            <!-- TODO: are these values even read by pybullet? -->
            <lateral_friction value="0.0"/>
            <rolling_friction value="0.0"/>
            <contact_cfm value="0.0"/>
            <contact_erp value="0.0"/>
        </contact>
  </link>
  
   <joint name="box_to_base" type="fixed">
    <parent link="base_link"/>
    <child link="box"/>
    <origin xyz="0 0 -0.05"/>
  </joint>


   <drake:collision_filter_group name="box_group">
  <drake:member link="box"/>
  <drake:ignored_collision_filter_group name="box_group"/>
  </drake:collision_filter_group>
  
  

</robot>
