<?xml version="1.0" encoding="utf-8"?>

<robot name="plate">
  <link name="base_link"/>
  <link name="plate_x"/>
  <link name="plate_y"/>
  <link name="plate">
    <inertial>
      <mass value="2.0"/>
      <inertia
          ixx="0.0067"
          ixy="0"
          ixz="0"
          iyy="0.0067"
          iyz="0"
          izz="0.013"/>
    </inertial>
    <visual>
      <origin rpy="0 0 0" xyz="0 0 0.01"/>
      <geometry>
        <box size="0.2 0.2 0.02"/>
      </geometry>
    </visual>
    <!--    <collision name="collision">-->
    <!--      <origin rpy="0 0 0" xyz="0 0 0.01"/>-->
    <!--      <geometry>-->
    <!--        <box size="0.2 0.2 0.02"/>-->
    <!--      </geometry>-->
    <!--      <drake:proximity_properties>-->
    <!--        <drake:rigid_hydroelastic/>-->
    <!--        <drake:mesh_resolution_hint value="1"/>-->
    <!--        <drake:mu_dynamic value="1.0"/>-->
    <!--        <drake:mu_static value="1.0"/>-->
    <!--      </drake:proximity_properties>-->
    <!--    </collision>-->
    <collision name="middle_right">
      <geometry>
        <sphere radius="0.01"/>
      </geometry>
      <origin rpy="0 0 0" xyz="0.5 0.0 0.01"/>
    </collision>
    <collision name="top_left">
      <geometry>
        <sphere radius="0.01"/>
      </geometry>
      <origin rpy="0 0 0" xyz="-0.5 0.5 0.01"/>
    </collision>
    <collision name="bottom_left">
      <geometry>
        <sphere radius="0.01"/>
      </geometry>
      <origin rpy="0 0 0" xyz="-0.5 -0.5 0.01"/>
    </collision>
  </link>
  <joint name="plate_x" type="prismatic">
    <parent link="base_link"/>
    <child link="plate_x"/>
    <axis xyz="1 0 0"/>
  </joint>
  <joint name="plate_y" type="prismatic">
    <parent link="plate_x"/>
    <child link="plate_y"/>
    <axis xyz="0 1 0"/>
  </joint>
  <joint name="plate_z" type="prismatic">
    <parent link="plate_y"/>
    <child link="plate"/>
    <axis xyz="0 0 1"/>
  </joint>
  <transmission name="plate_x" type="SimpleTransmission">
    <actuator name="plate_virtual_actuator_x"/>
    <joint name="plate_x"/>
    <mechanicalReduction>1</mechanicalReduction>
  </transmission>
  <transmission name="plate_y" type="SimpleTransmission">
    <actuator name="plate_virtual_actuator_y"/>
    <joint name="plate_y"/>
    <mechanicalReduction>1</mechanicalReduction>
  </transmission>
  <transmission name="plate_z" type="SimpleTransmission">
    <actuator name="plate_virtual_actuator_z"/>
    <joint name="plate_z"/>
    <mechanicalReduction>1</mechanicalReduction>
  </transmission>
</robot>
