<?xml version="1.0"?>
<sdf version="1.7">

    <model name="passive_block">
        <link name="base"/>
        <link name="base_x"/>
        <link name="base_xz"/>
        <link name="passive_block">
            <inertial>
                <pose>0 0 -0.05 0 0 0</pose>
                <mass>1</mass>
                <inertia>
                    <ixx>4e-07</ixx>
                    <ixy>0</ixy>
                    <ixz>0</ixz>
                    <iyy>0.04</iyy>
                    <iyz>0</iyz>
                    <izz>0.04</izz>
                </inertia>
            </inertial>
            <visual name="passive_block">
                <pose>0 0 0 0 0 0</pose>
                <material>
                    <diffuse>0.1 0.1 0.1 0.6</diffuse>
                </material>
                <geometry>
                    <box>
                        <size>0.4 0.4 0.1</size>
                    </box>
                </geometry>
            </visual>
            <collision name="left">
                <pose>-0.2 0.0 -0.048 0 0 0 </pose>
                <geometry>
                    <sphere>
                        <radius>0.001"</radius>
                    </sphere>
                </geometry>
            </collision>
            <collision name="right">
                <pose>0.2 0.0 -0.048 0 0 0 </pose>
                <geometry>
                    <sphere>
                        <radius>0.001"</radius>
                    </sphere>
                </geometry>
            </collision>
        </link>
        <joint name="planar_x" type="prismatic">
            <parent>base</parent>
            <child>base_x</child>
            <axis>
                <xyz>
                    1 0 0
                </xyz>
                <limit>
                    <effort>0.0</effort>
                </limit>
            </axis>
        </joint>
        <joint name="planar_z" type="prismatic">
            <parent>base_x</parent>
            <child>base_xz</child>
            <axis>
                <xyz>
                    0 0 1
                </xyz>
                <limit>
                    <effort>0.0</effort>
                </limit>
            </axis>
        </joint>
        <joint name="planar_roty" type="continuous">
            <parent>base_xz</parent>
            <child>passive_block</child>
            <axis>
                <xyz>
                    0 1 0
                </xyz>
                <limit>
                    <effort>0.0</effort>
                </limit>
            </axis>
        </joint>
    </model>

</sdf>