<?xml version="1.0" ?>
<robot name="pivoting">

    <material name="blue">
        <color rgba="0 0 1 1"/>
    </material>

    <material name="green">
        <color rgba="0 1 0 1"/>
    </material>

    <material name="red">
        <color rgba="1 0 0 1"/>
    </material>

    <material name="white">
        <color rgba="1 1 1 1"/>
    </material>

    <link name="base"/>
    <link name="base_x"/>
    <link name="base_z"/>
    <link name="box">
        <inertial>
            <mass value="12.0"/>
            <inertia ixx="1.33" ixy="0" ixz="0" iyy="1.33" iyz="0" izz="1.33"/>
        </inertial>
        <visual>
            <origin xyz="0 0 0"/>
            <geometry>
               <box size="2 2 2" />
            </geometry>
            <material name="blue"/>
        </visual>
    </link>
    <link name="finger_right">
        <visual>
            <origin xyz="1.05 0 0" rpy="0 0 0"/>
            <geometry>
                <sphere radius="0.2"/>           
            </geometry>
            <material name="red"/>
        </visual>
    </link>
    <link name="finger_left">
        <visual>
            <origin xyz="0 0 -1.05" rpy="0 0 0"/>
            <geometry>
                <sphere radius="0.2"/>           
            </geometry>
            <material name="red"/>
        </visual>
    </link>

   
    <joint name="box_x" type="prismatic">
        <parent link="base"/>
        <child link="base_x"/>
        <axis xyz="1 0 0"/>
    </joint>
	
    <joint name="box_z" type="prismatic">
        <parent link="base_x"/>
        <child link="base_z"/>
        <axis xyz="0 0 1"/>
    </joint>
    
    <joint name="box_angular" type="continuous">
        <parent link="base_z"/>
        <child link="box"/>
        <axis xyz="0 1 0"/>
    </joint>


    <joint name="finger_right" type="prismatic">
        <parent link="box"/>
        <child link="finger_right"/>
        <axis xyz="0 0 1"/>
    </joint>

    <joint name="finger_left" type="prismatic">
        <parent link="box"/>
        <child link="finger_left"/>
        <axis xyz="-1 0 0"/>
    </joint>

</robot>

